Workbook

Sheet Start here
B2: CLIMATE INSIDERS INVESTOR LISTS
B3: 500 European family office contacts
B4: Named decision makers across 300+ family offices. 18 countries.
B5: Prepared for Sam on 27 Oct 2026
B8: 62 | C8: 50 | D8: 60 | E8: 5
B9: contacts | C9: direct emails | D9: LinkedIn profiles | E9: countries
B11: How I'd work this list
A12: 1 | B12: Filter Seniority to "Decision maker" and start there. Fewer emails, better answers.
A13: 2 | B13: Before you write, read their last 3 deals. If you can't say in one line why they'd care, skip them.
A14: 3 | B14: Log every touch in Status and Last touch. The Pipeline tab counts replies and meetings for you.
B16: Status colors
B17: To contact | C17: Researching | D17: Emailed
B18: Followed up | C18: Replied | D18: Meeting booked
B19: In diligence | C19: Passed | D19: Not a fit
B21: Click the Europe tab below to start. The Status cell on every row is a dropdown.
B22: Found a wrong row? Reply to the email it came with and I fix it.
B24: Yoann
B25: Climate Insiders
B27: Every list: | C27: lists.climateinsiders.com/all

Sheet Europe
A1: 500 European family office contacts
A2: Climate Insiders Investor Lists | prepared for Sam, 27 Oct 2026 | 62 contacts, 50 with a direct email | most complete rows first
A4: # | B4: Name | C4: Title | D4: Firm | E4: Seniority | F4: Email | G4: LinkedIn | H4: City | I4: Country | J4: Website | K4: Status | L4: Last touch | M4: Notes
A5: 1 | B5: Harald Klien | C5: Chief Executive Officer | D5: Cd Invest Consult Gmbh | E5: Decision maker | F5: harald.klien@cdiconsult.com | G5: View profile | H5: Wien | I5: Austria | K5: To contact
A6: 2 | B6: Daniel Gillet | C6: Managing Partner Benelux | D6: Onetoone Corporate Finance | E6: Decision maker | F6: daniel.gillet@onetoonecf.com | G6: View profile | H6: Bruxelles | I6: Belgium | K6: To contact
A7: 3 | B7: Colette Plasman | C7: Co-Founder | D7: E-Spring Capital | E7: Decision maker | F7: colette@espringcapital.eu | G7: View profile | H7: Deurne | I7: Belgium | J7: espringcapital.eu | K7: To contact
A8: 4 | B8: Bart Wouters | C8: Founder & Managing Partner | D8: Strada Partners | E8: Decision maker | F8: bart.wouters@strada-partners.com | G8: View profile | H8: Antwerpen | I8: Belgium | J8: strada-partners.com | K8: To contact
A9: 5 | B9: Julie Lauwers | C9: Investment Director | D9: Syus | E9: Senior | F9: julie.lauwers@syus.be | G9: View profile | H9: Rekkem | I9: Belgium | J9: syus.be | K9: To contact
A10: 6 | B10: Petr Tmej | C10: Investment Analyst | D10: Comfort Zone Investments a.s. | E10: Investment team | F10: reach via LinkedIn | G10: View profile | H10: Nove Straseci | I10: Czech Republic | K10: To contact
A11: 7 | B11: Harald Klien | C11: Chief Executive Officer | D11: Cd Invest Consult Gmbh | E11: Decision maker | F11: harald.klien@cdiconsult.com | G11: View profile | H11: Wien | I11: Austria | K11: To contact
A12: 8 | B12: Daniel Gillet | C12: Managing Partner Benelux | D12: Onetoone Corporate Finance | E12: Decision maker | F12: daniel.gillet@onetoonecf.com | G12: View profile | H12: Bruxelles | I12: Belgium | K12: To contact
A13: 9 | B13: Colette Plasman | C13: Co-Founder | D13: E-Spring Capital | E13: Decision maker | F13: colette@espringcapital.eu | G13: View profile | H13: Deurne | I13: Belgium | J13: espringcapital.eu | K13: To contact
A14: 10 | B14: Bart Wouters | C14: Founder & Managing Partner | D14: Strada Partners | E14: Decision maker | F14: bart.wouters@strada-partners.com | G14: View profile | H14: Antwerpen | I14: Belgium | J14: strada-partners.com | K14: To contact
A15: 11 | B15: Julie Lauwers | C15: Investment Director | D15: Syus | E15: Senior | F15: julie.lauwers@syus.be | G15: View profile | H15: Rekkem | I15: Belgium | J15: syus.be | K15: To contact
A16: 12 | B16: Petr Tmej | C16: Investment Analyst | D16: Comfort Zone Investments a.s. | E16: Investment team | F16: reach via LinkedIn | G16: View profile | H16: Nove Straseci | I16: Czech Republic | K16: To contact
A17: 13 | B17: Harald Klien | C17: Chief Executive Officer | D17: Cd Invest Consult Gmbh | E17: Decision maker | F17: harald.klien@cdiconsult.com | G17: View profile | H17: Wien | I17: Austria | K17: To contact
A18: 14 | B18: Daniel Gillet | C18: Managing Partner Benelux | D18: Onetoone Corporate Finance | E18: Decision maker | F18: daniel.gillet@onetoonecf.com | G18: View profile | H18: Bruxelles | I18: Belgium | K18: To contact
A19: 15 | B19: Colette Plasman | C19: Co-Founder | D19: E-Spring Capital | E19: Decision maker | F19: colette@espringcapital.eu | G19: View profile | H19: Deurne | I19: Belgium | J19: espringcapital.eu | K19: To contact
A20: 16 | B20: Bart Wouters | C20: Founder & Managing Partner | D20: Strada Partners | E20: Decision maker | F20: bart.wouters@strada-partners.com | G20: View profile | H20: Antwerpen | I20: Belgium | J20: strada-partners.com | K20: To contact
A21: 17 | B21: Julie Lauwers | C21: Investment Director | D21: Syus | E21: Senior | F21: julie.lauwers@syus.be | G21: View profile | H21: Rekkem | I21: Belgium | J21: syus.be | K21: To contact
A22: 18 | B22: Petr Tmej | C22: Investment Analyst | D22: Comfort Zone Investments a.s. | E22: Investment team | F22: reach via LinkedIn | G22: View profile | H22: Nove Straseci | I22: Czech Republic | K22: To contact
A23: 19 | B23: Harald Klien | C23: Chief Executive Officer | D23: Cd Invest Consult Gmbh | E23: Decision maker | F23: harald.klien@cdiconsult.com | G23: View profile | H23: Wien | I23: Austria | K23: To contact
A24: 20 | B24: Daniel Gillet | C24: Managing Partner Benelux | D24: Onetoone Corporate Finance | E24: Decision maker | F24: daniel.gillet@onetoonecf.com | G24: View profile | H24: Bruxelles | I24: Belgium | K24: To contact
A25: 21 | B25: Colette Plasman | C25: Co-Founder | D25: E-Spring Capital | E25: Decision maker | F25: colette@espringcapital.eu | G25: View profile | H25: Deurne | I25: Belgium | J25: espringcapital.eu | K25: To contact
A26: 22 | B26: Bart Wouters | C26: Founder & Managing Partner | D26: Strada Partners | E26: Decision maker | F26: bart.wouters@strada-partners.com | G26: View profile | H26: Antwerpen | I26: Belgium | J26: strada-partners.com | K26: To contact
A27: 23 | B27: Julie Lauwers | C27: Investment Director | D27: Syus | E27: Senior | F27: julie.lauwers@syus.be | G27: View profile | H27: Rekkem | I27: Belgium | J27: syus.be | K27: To contact
A28: 24 | B28: Petr Tmej | C28: Investment Analyst | D28: Comfort Zone Investments a.s. | E28: Investment team | F28: reach via LinkedIn | G28: View profile | H28: Nove Straseci | I28: Czech Republic | K28: To contact
A29: 25 | B29: Harald Klien | C29: Chief Executive Officer | D29: Cd Invest Consult Gmbh | E29: Decision maker | F29: harald.klien@cdiconsult.com | G29: View profile | H29: Wien | I29: Austria | K29: To contact
A30: 26 | B30: Daniel Gillet | C30: Managing Partner Benelux | D30: Onetoone Corporate Finance | E30: Decision maker | F30: daniel.gillet@onetoonecf.com | G30: View profile | H30: Bruxelles | I30: Belgium | K30: To contact
A31: 27 | B31: Colette Plasman | C31: Co-Founder | D31: E-Spring Capital | E31: Decision maker | F31: colette@espringcapital.eu | G31: View profile | H31: Deurne | I31: Belgium | J31: espringcapital.eu | K31: To contact
A32: 28 | B32: Bart Wouters | C32: Founder & Managing Partner | D32: Strada Partners | E32: Decision maker | F32: bart.wouters@strada-partners.com | G32: View profile | H32: Antwerpen | I32: Belgium | J32: strada-partners.com | K32: To contact
A33: 29 | B33: Julie Lauwers | C33: Investment Director | D33: Syus | E33: Senior | F33: julie.lauwers@syus.be | G33: View profile | H33: Rekkem | I33: Belgium | J33: syus.be | K33: To contact
A34: 30 | B34: Petr Tmej | C34: Investment Analyst | D34: Comfort Zone Investments a.s. | E34: Investment team | F34: reach via LinkedIn | G34: View profile | H34: Nove Straseci | I34: Czech Republic | K34: To contact
A35: 31 | B35: Harald Klien | C35: Chief Executive Officer | D35: Cd Invest Consult Gmbh | E35: Decision maker | F35: harald.klien@cdiconsult.com | G35: View profile | H35: Wien | I35: Austria | K35: To contact
A36: 32 | B36: Daniel Gillet | C36: Managing Partner Benelux | D36: Onetoone Corporate Finance | E36: Decision maker | F36: daniel.gillet@onetoonecf.com | G36: View profile | H36: Bruxelles | I36: Belgium | K36: To contact
A37: 33 | B37: Colette Plasman | C37: Co-Founder | D37: E-Spring Capital | E37: Decision maker | F37: colette@espringcapital.eu | G37: View profile | H37: Deurne | I37: Belgium | J37: espringcapital.eu | K37: To contact
A38: 34 | B38: Bart Wouters | C38: Founder & Managing Partner | D38: Strada Partners | E38: Decision maker | F38: bart.wouters@strada-partners.com | G38: View profile | H38: Antwerpen | I38: Belgium | J38: strada-partners.com | K38: To contact
A39: 35 | B39: Julie Lauwers | C39: Investment Director | D39: Syus | E39: Senior | F39: julie.lauwers@syus.be | G39: View profile | H39: Rekkem | I39: Belgium | J39: syus.be | K39: To contact
A40: 36 | B40: Petr Tmej | C40: Investment Analyst | D40: Comfort Zone Investments a.s. | E40: Investment team | F40: reach via LinkedIn | G40: View profile | H40: Nove Straseci | I40: Czech Republic | K40: To contact
A41: 37 | B41: Harald Klien | C41: Chief Executive Officer | D41: Cd Invest Consult Gmbh | E41: Decision maker | F41: harald.klien@cdiconsult.com | G41: View profile | H41: Wien | I41: Austria | K41: To contact
...

Sheet Pipeline
B2: Your pipeline
B3: Updates itself from the Status column in the Europe tab.
B5: Status | C5: Count | D5: Share
B6: To contact | C6: =COUNTIF('Europe'!$K$5:$K$66,"To contact") | D6: =IFERROR(C6/SUM($C$6:$C$14),0) | E6: =C6
B7: Researching | C7: =COUNTIF('Europe'!$K$5:$K$66,"Researching") | D7: =IFERROR(C7/SUM($C$6:$C$14),0) | E7: =C7
B8: Emailed | C8: =COUNTIF('Europe'!$K$5:$K$66,"Emailed") | D8: =IFERROR(C8/SUM($C$6:$C$14),0) | E8: =C8
B9: Followed up | C9: =COUNTIF('Europe'!$K$5:$K$66,"Followed up") | D9: =IFERROR(C9/SUM($C$6:$C$14),0) | E9: =C9
B10: Replied | C10: =COUNTIF('Europe'!$K$5:$K$66,"Replied") | D10: =IFERROR(C10/SUM($C$6:$C$14),0) | E10: =C10
B11: Meeting booked | C11: =COUNTIF('Europe'!$K$5:$K$66,"Meeting booked") | D11: =IFERROR(C11/SUM($C$6:$C$14),0) | E11: =C11
B12: In diligence | C12: =COUNTIF('Europe'!$K$5:$K$66,"In diligence") | D12: =IFERROR(C12/SUM($C$6:$C$14),0) | E12: =C12
B13: Passed | C13: =COUNTIF('Europe'!$K$5:$K$66,"Passed") | D13: =IFERROR(C13/SUM($C$6:$C$14),0) | E13: =C13
B14: Not a fit | C14: =COUNTIF('Europe'!$K$5:$K$66,"Not a fit") | D14: =IFERROR(C14/SUM($C$6:$C$14),0) | E14: =C14
B16: Investors contacted | C16: =C8+C9+C10+C11+C12+C13
B17: Reply rate | C17: =IFERROR((C10+C11+C12+C13)/C16,0)
B18: Meetings | C18: =C11+C12
B20: Seniority | C20: Count | D20: Emailable
B21: Decision maker | C21: =COUNTIF('Europe'!$E$5:$E$66,"Decision maker") | D21: =COUNTIFS('Europe'!$E$5:$E$66,"Decision maker",'Europe'!$F$5:$F$66,"*@*")
B22: Senior | C22: =COUNTIF('Europe'!$E$5:$E$66,"Senior") | D22: =COUNTIFS('Europe'!$E$5:$E$66,"Senior",'Europe'!$F$5:$F$66,"*@*")
B23: Investment team | C23: =COUNTIF('Europe'!$E$5:$E$66,"Investment team") | D23: =COUNTIFS('Europe'!$E$5:$E$66,"Investment team",'Europe'!$F$5:$F$66,"*@*")
